Workbook

Sheet P1
B1: Marker | C1: LeftMallet1 | I1: LeftMallet2 | O1: LeftMallet3 | U1: RightMallet1 | AA1: RightMallet2 | AG1: RightMallet3
B2: Axis | C2: X | D2: Y | E2: Z | F2: X' | G2: Y' | H2: Z' | I2: X | J2: Y | K2: Z | L2: X' | M2: Y' | N2: Z' | O2: X | P2: Y | Q2: Z | R2: X' | S2: Y' | T2: Z' | U2: X | V2: Y | W2: Z | X2: X' | Y2: Y' | Z2: Z' | AA2: X | AB2: Y | AC2: Z | AD2: X' | AE2: Y' | AF2: Z' | AG2: X | AH2: Y | AI2: Z | AJ2: X' | AK2: Y' | AL2: Z'
A3: Trial | B3: Stats
A4: P101 Con T1 | B4: AVG | C4: 1209.6023 | D4: 955.02372 | E4: 1161.0066 | F4: 131.74076 | G4: 57.566261 | H4: 88.45038 | I4: 1310.8075 | J4: 1175.5724 | K4: 1220.6515 | L4: 830.45025 | M4: 635.21556 | N4: 467.71561 | O4: 1213.7039 | P4: 1044.9655 | Q4: 1182.926 | R4: 376.85006 | S4: 165.92281 | T4: 147.92934 | U4: 593.22278 | V4: 945.39252 | W4: 1180.4428 | X4: 92.272811 | Y4: 41.046773 | Z4: 92.07121 | AA4: 545.33395 | AB4: 1228.2929 | AC4: 1264.4438 | AD4: 667.40784 | AE4: 350.97899 | AF4: 341.86054 | AG4: 593.37769 | AH4: 1049.6204 | AI4: 1214.5744 | AJ4: 283.73823 | AK4: 106.89199 | AL4: 129.27556
B5: SD | C5: 24.377215 | D5: 13.784997 | E5: 13.936829 | F5: 127.50239 | G5: 52.401483 | H5: 68.090286 | I5: 161.71024 | J5: 108.87866 | K5: 64.055771 | L5: 1044.3851 | M5: 740.35664 | N5: 470.11138 | O5: 64.934036 | P5: 29.159621 | Q5: 19.660028 | R5: 451.58456 | S5: 186.25314 | T5: 123.24765 | U5: 16.759441 | V5: 8.273345 | W5: 16.229995 | X5: 72.878316 | Y5: 35.311486 | Z5: 72.904211 | AA5: 112.65129 | AB5: 64.366882 | AC5: 52.272858 | AD5: 851.59825 | AE5: 599.91655 | AF5: 395.71151 | AG5: 49.634401 | AH5: 19.802668 | AI5: 23.52764 | AJ5: 317.08602 | AK5: 158.85359 | AL5: 118.52639
A6: P101 Con T2 | B6: AVG | C6: 1194.6232 | D6: 969.58034 | E6: 1160.7144 | F6: 113.94876 | G6: 58.363371 | H6: 72.194569 | I6: 1264.0671 | J6: 1210.8645 | K6: 1230.078 | L6: 657.69852 | M6: 533.62083 | N6: 364.69767 | O6: 1186.7837 | P6: 1065.4966 | Q6: 1188.01 | R6: 295.51119 | S6: 134.93008 | T6: 113.47211 | U6: 591.80604 | V6: 950.27276 | W6: 1187.7712 | X6: 79.066654 | Y6: 39.232065 | Z6: 72.940607 | AA6: 559.55297 | AB6: 1234.478 | AC6: 1286.1177 | AD6: 570.94303 | AE6: 289.1356 | AF6: 286.48778 | AG6: 598.27346 | AH6: 1053.8266 | AI6: 1226.8134 | AJ6: 240.64185 | AK6: 97.223183 | AL6: 102.20366
B7: SD | C7: 22.636608 | D7: 17.568714 | E7: 16.886624 | F7: 116.20346 | G7: 48.828718 | H7: 64.477148 | I7: 145.33831 | J7: 105.46517 | K7: 71.772714 | L7: 850.27464 | M7: 726.95245 | N7: 446.46594 | O7: 53.931675 | P7: 26.278015 | Q7: 25.646997 | R7: 361.86648 | S7: 168.27533 | T7: 115.65642 | U7: 13.640469 | V7: 7.7150067 | W7: 12.283646 | X7: 77.535055 | Y7: 30.907991 | Z7: 58.715216 | AA7: 102.69564 | AB7: 57.268953 | AC7: 44.514987 | AD7: 795.94532 | AE7: 519.53112 | AF7: 354.00482 | AG7: 43.66649 | AH7: 17.620644 | AI7: 17.505669 | AJ7: 321.48192 | AK7: 167.91573 | AL7: 90.063432
A8: P101 Con T3 | B8: AVG | C8: 1176.6729 | D8: 968.21084 | E8: 1162.8231 | F8: 118.93496 | G8: 72.552867 | H8: 84.652979 | I8: 1243.7102 | J8: 1216.3314 | K8: 1232.8096 | L8: 761.10784 | M8: 537.5263 | N8: 405.05518 | O8: 1170.0972 | P8: 1064.0556 | Q8: 1188.2173 | R8: 322.93939 | S8: 140.14364 | T8: 131.65494 | U8: 571.62203 | V8: 932.35858 | W8: 1188.9158 | X8: 91.700421 | Y8: 34.898813 | Z8: 62.166891 | AA8: 500.27886 | AB8: 1198.7493 | AC8: 1284.302 | AD8: 671.72826 | AE8: 405.59613 | AF8: 310.57227 | AG8: 563.21703 | AH8: 1032.2214 | AI8: 1227.6391 | AJ8: 286.62391 | AK8: 119.27801 | AL8: 105.23193
B9: SD | C9: 22.296533 | D9: 15.847857 | E9: 15.709829 | F9: 113.70023 | G9: 51.93292 | H9: 64.583725 | I9: 135.92219 | J9: 92.729997 | K9: 65.184996 | L9: 857.21348 | M9: 704.60267 | N9: 436.24811 | O9: 50.171202 | P9: 23.059079 | Q9: 23.235837 | R9: 353.56883 | S9: 145.33674 | T9: 110.44624 | U9: 17.29654 | V9: 10.783443 | W9: 13.920414 | X9: 87.361577 | Y9: 30.832851 | Z9: 50.124832 | AA9: 124.9041 | AB9: 71.580852 | AC9: 57.666522 | AD9: 839.3764 | AE9: 592.52258 | AF9: 373.62723 | AG9: 55.217266 | AH9: 23.584855 | AI9: 23.593171 | AJ9: 339.21637 | AK9: 157.18432 | AL9: 100.36929
A10: P101 Con T4 | B10: AVG | C10: 1179.6851 | D10: 948.13299 | E10: 1154.1207 | F10: 163.30127 | G10: 59.774444 | H10: 86.789255 | I10: 1303.341 | J10: 1151.0841 | K10: 1189.8874 | L10: 985.20632 | M10: 846.24457 | N10: 541.74119 | O10: 1185.8001 | P10: 1035.4036 | Q10: 1176.6075 | R10: 468.43181 | S10: 205.26096 | T10: 154.80961 | U10: 554.12048 | V10: 904.08518 | W10: 1182.4583 | X10: 96.578784 | Y10: 38.049073 | Z10: 83.680115 | AA10: 473.61011 | AB10: 1169.5031 | AC10: 1263.5082 | AD10: 829.53022 | AE10: 530.03124 | AF10: 370.93514 | AG10: 544.18462 | AH10: 1003.3791 | AI10: 1217.2665 | AJ10: 336.67282 | AK10: 152.67826 | AL10: 113.55997
B11: SD | C11: 23.342603 | D11: 11.479193 | E11: 10.535844 | F11: 134.27 | G11: 49.374755 | H11: 70.326875 | I11: 148.31174 | J11: 124.96888 | K11: 63.221028 | L11: 1048.6849 | M11: 849.99779 | N11: 516.64479 | O11: 55.669042 | P11: 27.067892 | Q11: 17.000304 | R11: 444.51669 | S11: 203.55914 | T11: 138.41551 | U11: 14.938697 | V11: 12.052567 | W11: 13.242795 | X11: 78.447671 | Y11: 34.233239 | Z11: 63.886998 | AA11: 113.30538 | AB11: 77.578237 | AC11: 49.839975 | AD11: 862.52612 | AE11: 698.42873 | AF11: 414.90493 | AG11: 46.259651 | AH11: 24.324805 | AI11: 19.209574 | AJ11: 318.97655 | AK11: 183.18436 | AL11: 104.95346
A12: P101 Con T5 | B12: AVG | C12: 1140.6337 | D12: 946.33471 | E12: 1151.8417 | F12: 121.18923 | G12: 53.952807 | H12: 66.93342 | I12: 1180.4394 | J12: 1209.3311 | K12: 1207.9997 | L12: 750.01175 | M12: 470.61154 | N12: 340.68485 | O12: 1135.4369 | P12: 1034.8657 | Q12: 1176.7922 | R12: 335.02686 | S12: 155.04081 | T12: 118.18525 | U12: 548.62263 | V12: 871.5282 | W12: 1181.1546 | X12: 79.695372 | Y12: 44.3393 | Z12: 74.338443 | AA12: 490.11999 | AB12: 1151.9241 | AC12: 1272.9173 | AD12: 549.52497 | AE12: 306.22258 | AF12: 265.55382 | AG12: 546.15374 | AH12: 974.86138 | AI12: 1218.7312 | AJ12: 217.89647 | AK12: 98.830634 | AL12: 102.31473
B13: SD | C13: 22.714426 | D13: 16.871741 | E13: 13.338708 | F13: 104.39221 | G13: 40.861719 | H13: 55.35356 | I13: 135.88278 | J13: 78.353095 | K13: 54.467021 | L13: 855.40678 | M13: 672.00345 | N13: 368.69852 | O13: 58.38672 | P13: 28.433579 | Q13: 22.039824 | R13: 354.20926 | S13: 183.9959 | T13: 107.39618 | U13: 12.957404 | V13: 17.602653 | W13: 13.544462 | X13: 63.421406 | Y13: 40.35005 | Z13: 58.006673 | AA13: 100.33559 | AB13: 65.439135 | AC13: 43.538727 | AD13: 716.28573 | AE13: 508.30949 | AF13: 325.43318 | AG13: 41.100047 | AH13: 24.834966 | AI13: 18.830519 | AJ13: 264.04737 | AK13: 139.0845 | AL13: 87.965577
A14: P101 Con T6 | B14: AVG | C14: 1171.9508 | D14: 902.56817 | E14: 1158.4313 | F14: 148.59724 | G14: 56.424045 | H14: 77.890569 | I14: 1237.2902 | J14: 1143.0714 | K14: 1217.8884 | L14: 785.87222 | M14: 557.18134 | N14: 417.13757 | O14: 1168.6678 | P14: 989.02001 | Q14: 1185.807 | R14: 369.35976 | S14: 155.96431 | T14: 129.59244 | U14: 570.49828 | V14: 871.53879 | W14: 1184.2652 | X14: 95.09579 | Y14: 31.582107 | Z14: 74.207485 | AA14: 538.23879 | AB14: 1155.2331 | AC14: 1279.0229 | AD14: 574.87169 | AE14: 313.88003 | AF14: 270.32225 | AG14: 577.60251 | AH14: 974.73788 | AI14: 1222.9296 | AJ14: 242.20094 | AK14: 84.055538 | AL14: 95.943397
B15: SD | C15: 23.976634 | D15: 17.343813 | E15: 12.290822 | F15: 135.32626 | G15: 46.436898 | H15: 60.529678 | I15: 142.48355 | J15: 102.61173 | K15: 64.698359 | L15: 938.05539 | M15: 775.28227 | N15: 467.91576 | O15: 57.088232 | P15: 30.638649 | Q15: 20.833944 | R15: 412.53795 | S15: 194.62771 | T15: 118.96773 | U15: 15.543166 | V15: 8.2011933 | W15: 14.038452 | X15: 80.607334 | Y15: 29.331771 | Z15: 60.320803 | AA15: 105.39833 | AB15: 62.080828 | AC15: 43.615944 | AD15: 861.911 | AE15: 584.86936 | AF15: 367.65364 | AG15: 44.218785 | AH15: 19.111285 | AI15: 18.624442 | AJ15: 323.81131 | AK15: 132.20818 | AL15: 87.145364
A16: P101 Con T7 | B16: AVG | C16: 1177.9315 | D16: 889.21358 | E16: 1156.161 | F16: 119.76265 | G16: 55.090512 | H16: 68.260204 | I16: 1249.7601 | J16: 1121.5521 | K16: 1218.2966 | L16: 640.13214 | M16: 516.55477 | N16: 355.30394 | O16: 1178.4107 | P16: 973.1704 | Q16: 1185.5733 | R16: 299.65115 | S16: 154.80108 | T16: 116.56271 | U16: 576.99182 | V16: 859.04142 | W16: 1178.9117 | X16: 92.105003 | Y16: 36.03257 | Z16: 60.552343 | AA16: 535.05083 | AB16: 1143.3565 | AC16: 1271.9239 | AD16: 624.69298 | AE16: 308.53005 | AF16: 278.25561 | AG16: 578.76073 | AH16: 963.09632 | AI16: 1217.6361 | AJ16: 290.62526 | AK16: 95.325275 | AL16: 95.651168
B17: SD | C17: 26.508764 | D17: 17.174982 | E17: 12.320693 | F17: 120.07614 | G17: 44.736817 | H17: 60.887235 | I17: 152.31266 | J17: 115.92545 | K17: 62.819743 | L17: 848.27334 | M17: 760.12448 | N17: 438.58591 | O17: 64.873167 | P17: 36.064474 | Q17: 20.457112 | R17: 376.62573 | S17: 208.4119 | T17: 120.40457 | U17: 15.687812 | V17: 6.7670913 | W17: 12.117324 | X17: 86.233981 | Y17: 31.873723 | Z17: 51.320938 | AA17: 106.36632 | AB17: 58.548133 | AC17: 44.787894 | AD17: 792.39205 | AE17: 531.64468 | AF17: 365.77794 | AG17: 46.399984 | AH17: 17.840257 | AI17: 17.951861 | AJ17: 369.98583 | AK17: 136.50318 | AL17: 103.21893
A18: P101 Con T8 | B18: AVG | C18: 1192.0698 | D18: 863.65912 | E18: 1149.0045 | F18: 138.40349 | G18: 62.775501 | H18: 65.984198 | I18: 1281.1983 | J18: 1097.5037 | K18: 1194.742 | L18: 706.00546 | M18: 578.37786 | N18: 330.25908 | O18: 1203.0653 | P18: 944.7057 | Q18: 1173.7686 | R18: 335.92147 | S18: 187.75129 | T18: 111.01709 | U18: 589.44262 | V18: 848.29665 | W18: 1182.9569 | X18: 88.539958 | Y18: 40.001795 | Z18: 67.338296 | AA18: 535.53041 | AB18: 1126.4527 | AC18: 1275.656 | AD18: 687.34467 | AE18: 389.60611 | AF18: 307.69618 | AG18: 587.16402 | AH18: 949.97252 | AI18: 1222.4959 | AJ18: 275.82933 | AK18: 117.49711 | AL18: 95.900301
B19: SD | C19: 23.519051 | D19: 14.787638 | E19: 11.25067 | F19: 111.95632 | G19: 46.014289 | H19: 56.017196 | I19: 143.01001 | J19: 110.59497 | K19: 55.606414 | L19: 836.98901 | M19: 756.84642 | N19: 354.0571 | O19: 63.91308 | P19: 35.766479 | Q19: 19.779969 | R19: 368.73145 | S19: 219.73555 | T19: 102.74908 | U19: 12.810914 | V19: 12.164669 | W19: 11.428714 | X19: 83.340153 | Y19: 37.56458 | Z19: 56.022373 | AA19: 105.65323 | AB19: 63.218949 | AC19: 45.652973 | AD19: 871.13035 | AE19: 596.61962 | AF19: 383.24705 | AG19: 42.836343 | AH19: 21.686984 | AI19: 17.02591 | AJ19: 321.324 | AK19: 155.00036 | AL19: 92.937958
A20: P101 Con T9 | B20: AVG | C20: 1183.4359 | D20: 864.21315 | E20: 1152.3989 | F20: 147.68898 | G20: 63.787344 | H20: 72.205678 | I20: 1267.3863 | J20: 1096.4966 | K20: 1197.6257 | L20: 812.0912 | M20: 641.68762 | N20: 402.17889 | O20: 1190.8433 | P20: 945.80674 | Q20: 1178.4665 | R20: 386.45525 | S20: 201.96996 | T20: 131.26469 | U20: 584.02145 | V20: 829.67386 | W20: 1181.7317 | X20: 108.68259 | Y20: 39.416622 | Z20: 78.379157 | AA20: 524.24038 | AB20: 1108.4218 | AC20: 1274.0673 | AD20: 734.14518 | AE20: 371.30231 | AF20: 313.08733 | AG20: 580.84062 | AH20: 931.29339 | AI20: 1221.446 | AJ20: 300.09856 | AK20: 106.23313 | AL20: 100.94338
B21: SD | C21: 20.397402 | D21: 13.210621 | E21: 10.829033 | F21: 124.97372 | G21: 42.97076 | H21: 57.18767 | I21: 143.80951 | J21: 110.93684 | K21: 56.536658 | L21: 893.0304 | M21: 798.76 | N21: 428.41107 | O21: 59.507417 | P21: 33.852149 | Q21: 18.28189 | R21: 388.77206 | S21: 222.58535 | T21: 118.41016 | U21: 15.181453 | V21: 14.149773 | W21: 12.301059 | X21: 81.976439 | Y21: 34.198489 | Z21: 63.342952 | AA21: 102.54026 | AB21: 58.529338 | AC21: 44.447642 | AD21: 791.35153 | AE21: 551.84915 | AF21: 370.13033 | AG21: 43.126466 | AH21: 20.331138 | AI21: 18.002317 | AJ21: 290.60186 | AK21: 140.83056 | AL21: 93.895297
A22: P101 Con T10 | B22: AVG | C22: 1188.4234 | D22: 846.18138 | E22: 1144.8529 | F22: 165.40946 | G22: 60.855317 | H22: 62.564096 | I22: 1287.6906 | J22: 1075.7969 | K22: 1177.2241 | L22: 909.78544 | M22: 731.00131 | N22: 465.29034 | O22: 1198.6313 | P22: 929.3312 | Q22: 1166.6686 | R22: 441.59859 | S22: 209.69104 | T22: 135.39311 | U22: 583.62117 | V22: 816.5602 | W22: 1179.3751 | X22: 121.53639 | Y22: 35.972615 | Z22: 78.645112 | AA22: 494.96239 | AB22: 1068.8104 | AC22: 1258.1207 | AD22: 860.85326 | AE22: 569.54787 | AF22: 422.51528 | AG22: 569.07516 | AH22: 910.42437 | AI22: 1216.002 | AJ22: 336.77858 | AK22: 150.50741 | AL22: 114.34056
B23: SD | C23: 18.651627 | D23: 11.552674 | E23: 7.1506162 | F23: 119.85808 | G23: 38.31726 | H23: 50.506784 | I23: 133.52054 | J23: 109.41916 | K23: 53.892647 | L23: 913.87195 | M23: 834.15099 | N23: 468.41291 | O23: 54.260475 | P23: 29.44575 | Q23: 14.374396 | R23: 404.40478 | S23: 219.10293 | T23: 126.64536 | U23: 17.881376 | V23: 10.18466 | W23: 13.567026 | X23: 103.11943 | Y23: 30.409355 | Z23: 60.949406 | AA23: 126.36427 | AB23: 94.690261 | AC23: 60.300356 | AD23: 931.15051 | AE23: 740.63612 | AF23: 456.08594 | AG23: 55.754196 | AH23: 30.905818 | AI23: 21.050977 | AJ23: 327.43389 | AK23: 184.96303 | AL23: 98.429336
A24: P101 Ctl T1 | B24: AVG | C24: 1169.349 | D24: 925.23562 | E24: 1154.2861 | F24: 139.11926 | G24: 59.524414 | H24: 76.131972 | I24: 1261.2282 | J24: 1163.4299 | K24: 1201.1857 | L24: 788.38739 | M24: 609.84449 | N24: 345.99461 | O24: 1169.3234 | P24: 1019.829 | Q24: 1171.683 | R24: 340.71353 | S24: 139.8928 | T24: 100.4376 | U24: 563.81841 | V24: 921.66547 | W24: 1184.4281 | X24: 84.58423 | Y24: 36.570618 | Z24: 76.833096 | AA24: 512.97894 | AB24: 1196.8004 | AC24: 1268.61 | AD24: 661.75638 | AE24: 382.80487 | AF24: 322.65876 | AG24: 565.99898 | AH24: 1020.5893 | AI24: 1226.869 | AJ24: 233.95982 | AK24: 95.932541 | AL24: 104.00565
B25: SD | C25: 25.00318 | D25: 20.407024 | E25: 13.380364 | F25: 116.16188 | G25: 42.897508 | H25: 59.773612 | I25: 147.55472 | J25: 104.41639 | K25: 54.744974 | L25: 848.45309 | M25: 748.16202 | N25: 355.17255 | O25: 59.797294 | P25: 29.407878 | Q25: 19.374134 | R25: 347.21061 | S25: 153.05556 | T25: 86.191802 | U25: 15.594837 | V25: 13.652216 | W25: 14.072512 | X25: 70.615324 | Y25: 29.152182 | Z25: 59.792947 | AA25: 114.70508 | AB25: 71.589443 | AC25: 51.629281 | AD25: 838.26264 | AE25: 590.77132 | AF25: 385.47276 | AG25: 44.865019 | AH25: 23.333399 | AI25: 20.690488 | AJ25: 274.61162 | AK25: 129.3414 | AL25: 92.540339
A26: P101 Ctl T2 | B26: AVG | C26: 1155.801 | D26: 904.77878 | E26: 1149.9952 | F26: 144.17366 | G26: 63.783809 | H26: 71.312842 | I26: 1239.4984 | J26: 1152.5173 | K26: 1192.8944 | L26: 871.65076 | M26: 573.60559 | N26: 366.00248 | O26: 1155.2451 | P26: 998.47124 | Q26: 1165.5575 | R26: 373.75666 | S26: 140.78573 | T26: 106.60223 | U26: 546.43668 | V26: 881.22684 | W26: 1180.0515 | X26: 86.111906 | Y26: 45.930568 | Z26: 77.824264 | AA26: 465.99557 | AB26: 1116.4591 | AC26: 1251.1526 | AD26: 710.20395 | AE26: 446.52958 | AF26: 357.2266 | AG26: 525.25133 | AH26: 998.07942 | AI26: 1225.5674 | AJ26: 384.81259 | AK26: 194.99823 | AL26: 163.7766
B27: SD | C27: 19.810193 | D27: 11.762951 | E27: 9.7141568 | F27: 104.93592 | G27: 44.544166 | H27: 61.114667 | I27: 135.01765 | J27: 88.688402 | K27: 42.852452 | L27: 848.55166 | M27: 688.80068 | N27: 384.2767 | O27: 50.620087 | P27: 22.654709 | Q27: 12.084803 | R27: 335.82179 | S27: 138.31095 | T27: 98.772055 | U27: 15.952643 | V27: 23.872287 | W27: 15.501474 | X27: 70.955461 | Y27: 36.537623 | Z27: 59.663219 | AA27: 121.3911 | AB27: 87.337291 | AC27: 51.502109 | AD27: 820.37787 | AE27: 605.584 | AF27: 419.99233 | AG27: 66.641832 | AH27: 84.830545 | AI27: 36.62035 | AJ27: 477.63001 | AK27: 329.63928 | AL27: 207.30313
A28: P101 Ctl T3 | B28: AVG | C28: 1131.5815 | D28: 901.26649 | E28: 1161.7058 | F28: 113.7279 | G28: 68.196971 | H28: 73.617351 | I28: 1150.3372 | J28: 1177.2823 | K28: 1225.4598 | L28: 672.947 | M28: 350.18029 | N28: 253.19276 | O28: 1115.5234 | P28: 995.92609 | Q28: 1181.8598 | R28: 283.56173 | S28: 118.01284 | T28: 91.349212 | U28: 541.49672 | V28: 852.47787 | W28: 1187.8306 | X28: 75.029522 | Y28: 32.335441 | Z28: 78.396936 | AA28: 500.42781 | AB28: 1138.2248 | AC28: 1285.5868 | AD28: 467.83865 | AE28: 259.72734 | AF28: 244.10211 | AG28: 543.72428 | AH28: 953.88614 | AI28: 1232.3677 | AJ28: 163.35445 | AK28: 72.888385 | AL28: 94.915634
B29: SD | C29: 17.862489 | D29: 15.503709 | E29: 11.615954 | F29: 108.20343 | G29: 54.231445 | H29: 61.336883 | I29: 113.50056 | J29: 61.198856 | K29: 37.499256 | L29: 815.68974 | M29: 554.61282 | N29: 302.75968 | O29: 42.131 | P29: 21.689552 | Q29: 14.326998 | R29: 299.49652 | S29: 133.69912 | T29: 82.031605 | U29: 13.077601 | V29: 10.469221 | W29: 11.109869 | X29: 63.679947 | Y29: 28.855899 | Z29: 59.624311 | AA29: 92.840877 | AB29: 59.218569 | AC29: 42.930615 | AD29: 707.54999 | AE29: 487.16837 | AF29: 314.00185 | AG29: 37.823949 | AH29: 22.23899 | AI29: 17.934903 | AJ29: 209.0335 | AK29: 114.01641 | AL29: 70.554609
A30: P101 Ctl T4 | B30: AVG | C30: 1132.2834 | D30: 871.39524 | E30: 1161.5189 | F30: 106.0355 | G30: 57.398099 | H30: 69.910796 | I30: 1164.4474 | J30: 1141.3546 | K30: 1219.4192 | L30: 614.0524 | M30: 411.85372 | N30: 279.42628 | O30: 1121.3934 | P30: 964.45579 | Q30: 1183.2305 | R30: 262.28778 | S30: 127.35891 | T30: 97.896802 | U30: 539.20699 | V30: 829.97716 | W30: 1189.4547 | X30: 95.963235 | Y30: 35.301703 | Z30: 81.749747 | AA30: 482.267 | AB30: 1096.7343 | AC30: 1279.7848 | AD30: 687.49851 | AE30: 449.60672 | AF30: 343.90099 | AG30: 538.99668 | AH30: 926.54301 | AI30: 1233.1622 | AJ30: 279.7673 | AK30: 128.34217 | AL30: 114.55295
B31: SD | C31: 16.723831 | D31: 19.167349 | E31: 13.240883 | F31: 92.166263 | G31: 47.390522 | H31: 55.577586 | I31: 118.49804 | J31: 77.393824 | K31: 49.796764 | L31: 792.10236 | M31: 650.67935 | N31: 337.36763 | O31: 45.788625 | P31: 28.045187 | Q31: 20.023158 | R31: 319.8562 | S31: 163.38153 | T31: 96.137653 | U31: 16.000679 | V31: 13.995855 | W31: 11.12443 | X31: 84.374985 | Y31: 35.799649 | Z31: 58.911253 | AA31: 117.33467 | AB31: 85.978123 | AC31: 55.129531 | AD31: 899.83748 | AE31: 694.80271 | AF31: 399.34007 | AG31: 47.075399 | AH31: 30.378547 | AI31: 19.524769 | AJ31: 329.63499 | AK31: 182.37878 | AL31: 95.463113
A32: P101 Ctl T5 | B32: AVG | C32: 1134.8536 | D32: 838.20911 | E32: 1157.6805 | F32: 170.9501 | G32: 62.333832 | H32: 79.392897 | I32: 1212.9564 | J32: 1065.5909 | K32: 1185.4941 | L32: 887.35353 | M32: 698.37157 | N32: 444.80018 | O32: 1125.5494 | P32: 928.47209 | Q32: 1175.8275 | R32: 432.455 | S32: 174.25178 | T32: 132.88675 | U32: 530.14467 | V32: 804.26015 | W32: 1181.4823 | X32: 85.802512 | Y32: 38.393815 | Z32: 85.793673 | AA32: 466.69355 | AB32: 1077.3392 | AC32: 1255.409 | AD32: 700.64417 | AE32: 455.65176 | AF32: 388.05879 | AG32: 528.19449 | AH32: 903.27785 | AI32: 1223.7018 | AJ32: 264.42313 | AK32: 113.4662 | AL32: 124.28414
B33: SD | C33: 22.735558 | D33: 14.400905 | E33: 11.09716 | F33: 133.43128 | G33: 54.012724 | H33: 66.622835 | I33: 151.36182 | J33: 119.64586 | K33: 57.738466 | L33: 983.55347 | M33: 848.9171 | N33: 451.52352 | O33: 52.721487 | P33: 25.849528 | Q33: 15.679716 | R33: 430.38001 | S33: 203.76533 | T33: 117.79566 | U33: 13.9088 | V33: 11.695567 | W33: 13.357859 | X33: 74.720848 | Y33: 29.880447 | Z33: 66.858582 | AA33: 110.17343 | AB33: 76.574885 | AC33: 57.676658 | AD33: 871.35265 | AE33: 684.05338 | AF33: 469.8795 | AG33: 43.042603 | AH33: 23.008768 | AI33: 20.826213 | AJ33: 315.38098 | AK33: 155.66994 | AL33: 118.23527
A34: P101 Ctl T6 | B34: AVG | C34: 1134.9174 | D34: 822.62166 | E34: 1155.6374 | F34: 128.41079 | G34: 62.621868 | H34: 79.529988 | I34: 1211.7701 | J34: 1067.9328 | K34: 1189.095 | L34: 860.87797 | M34: 618.98616 | N34: 402.13762 | O34: 1139.943 | P34: 907.69806 | Q34: 1175.9086 | R34: 377.51828 | S34: 196.49818 | T34: 133.93511 | U34: 537.30744 | V34: 788.11797 | W34: 1180.9035 | X34: 96.481385 | Y34: 40.122752 | Z34: 81.72444 | AA34: 471.86399 | AB34: 1067.7782 | AC34: 1255.8012 | AD34: 675.06878 | AE34: 372.28231 | AF34: 336.33935 | AG34: 531.14332 | AH34: 886.79683 | AI34: 1222.3409 | AJ34: 282.62723 | AK34: 115.71476 | AL34: 125.9822
B35: SD | C35: 18.531806 | D35: 13.243955 | E35: 10.213165 | F35: 104.65752 | G35: 43.108036 | H35: 61.591447 | I35: 133.36907 | J35: 100.25662 | K35: 48.920892 | L35: 884.68437 | M35: 764.54004 | N35: 431.4079 | O35: 54.319963 | P35: 32.686155 | Q35: 16.753536 | R35: 370.42489 | S35: 211.60329 | T35: 127.57369 | U35: 15.849549 | V35: 14.964514 | W35: 14.316192 | X35: 78.391486 | Y35: 35.657161 | Z35: 58.908098 | AA35: 108.90272 | AB35: 62.870911 | AC35: 47.942863 | AD35: 812.63609 | AE35: 546.81814 | AF35: 374.98054 | AG35: 47.180748 | AH35: 24.557165 | AI35: 20.518589 | AJ35: 324.07449 | AK35: 145.11584 | AL35: 107.2096
A36: P101 Ctl T7 | B36: AVG | C36: 1126.0725 | D36: 803.4971 | E36: 1151.4369 | F36: 132.26195 | G36: 57.479875 | H36: 66.015592 | I36: 1201.2694 | J36: 1053.3854 | K36: 1187.9643 | L36: 719.813 | M36: 505.1316 | N36: 302.82126 | O36: 1132.3022 | P36: 888.7714 | Q36: 1176.3331 | R36: 339.10237 | S36: 170.13627 | T36: 106.74429 | U36: 533.24536 | V36: 765.30518 | W36: 1184.3379 | X36: 102.2233 | Y36: 36.722771 | Z36: 88.201033 | AA36: 485.26924 | AB36: 1051.0527 | AC36: 1267.4906 | AD36: 556.54937 | AE36: 293.75866 | AF36: 300.22737 | AG36: 538.80219 | AH36: 869.73967 | AI36: 1230.3327 | AJ36: 216.74938 | AK36: 76.363903 | AL36: 113.49249
B37: SD | C37: 21.948399 | D37: 14.684099 | E37: 12.075684 | F37: 107.92151 | G37: 44.131259 | H37: 56.339113 | I37: 141.40628 | J37: 94.276679 | K37: 55.760819 | L37: 750.61613 | M37: 654.46398 | N37: 309.96893 | O37: 63.75867 | P37: 31.550887 | Q37: 20.33923 | R37: 343.56575 | S37: 188.25488 | T37: 95.000033 | U37: 16.869653 | V37: 12.077684 | W37: 14.015182 | X37: 77.264024 | Y37: 32.16223 | Z37: 72.283143 | AA37: 98.933855 | AB37: 66.462158 | AC37: 52.190102 | AD37: 756.64382 | AE37: 526.67259 | AF37: 392.173 | AG37: 33.893732 | AH37: 17.492576 | AI37: 19.085343 | AJ37: 234.32057 | AK37: 116.18844 | AL37: 117.08882
A38: P101 Ctl T8 | B38: AVG | C38: 1130.4354 | D38: 801.03515 | E38: 1151.672 | F38: 137.28607 | G38: 61.903008 | H38: 78.326441 | I38: 1198.6902 | J38: 1048.8256 | K38: 1192.0439 | L38: 838.7619 | M38: 593.02359 | N38: 354.21592 | O38: 1133.2852 | P38: 885.17443 | Q38: 1178.6819 | R38: 390.8401 | S38: 187.4616 | T38: 122.72014 | U38: 537.2813 | V38: 755.39062 | W38: 1182.5232 | X38: 95.156249 | Y38: 39.150966 | Z38: 81.540331 | AA38: 464.7354 | AB38: 1026.9116 | AC38: 1255.844 | AD38: 678.02949 | AE38: 453.51715 | AF38: 390.68885 | AG38: 533.90382 | AH38: 856.13778 | AI38: 1226.1536 | AJ38: 239.49127 | AK38: 101.32873 | AL38: 113.20877
B39: SD | C39: 20.166415 | D39: 13.303619 | E39: 11.889838 | F39: 113.79506 | G39: 47.152371 | H39: 65.901295 | I39: 136.9651 | J39: 99.008906 | K39: 51.904288 | L39: 905.37069 | M39: 784.35111 | N39: 379.51884 | O39: 59.910677 | P39: 31.379059 | Q39: 18.898433 | R39: 389.78606 | S39: 212.09713 | T39: 116.25692 | U39: 14.54288 | V39: 15.30965 | W39: 13.428303 | X39: 79.328206 | Y39: 37.439518 | Z39: 66.989504 | AA39: 107.95449 | AB39: 80.620473 | AC39: 57.327082 | AD39: 884.78599 | AE39: 667.63848 | AF39: 457.25683 | AG39: 39.815145 | AH39: 24.757 | AI39: 19.639452 | AJ39: 283.41633 | AK39: 140.47138 | AL39: 97.118785
A40: P101 Ctl T9 | B40: AVG | C40: 1138.9687 | D40: 768.53579 | E40: 1147.3623 | F40: 148.10549 | G40: 67.584897 | H40: 82.371409 | I40: 1213.1705 | J40: 1015.0667 | K40: 1176.197 | L40: 842.17668 | M40: 647.15337 | N40: 368.82774 | O40: 1143.571 | P40: 853.07446 | Q40: 1172.352 | R40: 406.37211 | S40: 205.5333 | T40: 129.81902 | U40: 541.24072 | V40: 737.57643 | W40: 1178.089 | X40: 104.75635 | Y40: 48.503301 | Z40: 97.16515 | AA40: 471.47227 | AB40: 1010.5872 | AC40: 1247.9356 | AD40: 811.99857 | AE40: 479.35609 | AF40: 400.27665 | AG40: 538.48253 | AH40: 836.71293 | AI40: 1222.5144 | AJ40: 313.82666 | AK40: 127.73487 | AL40: 126.12347
...

Sheet P2
B1: Marker | C1: LeftMallet1 | I1: LeftMallet2 | O1: LeftMallet3 | U1: RightMallet1 | AA1: RightMallet2 | AG1: RightMallet3
B2: Axis | C2: X | D2: Y | E2: Z | F2: X' | G2: Y' | H2: Z' | I2: X | J2: Y | K2: Z | L2: X' | M2: Y' | N2: Z' | O2: X | P2: Y | Q2: Z | R2: X' | S2: Y' | T2: Z' | U2: X | V2: Y | W2: Z | X2: X' | Y2: Y' | Z2: Z' | AA2: X | AB2: Y | AC2: Z | AD2: X' | AE2: Y' | AF2: Z' | AG2: X | AH2: Y | AI2: Z | AJ2: X' | AK2: Y' | AL2: Z'
A3: Trial | B3: Stats
A4: Con1 | B4: AVG | C4: 1395.6817 | D4: 1133.6191 | E4: 1093.076 | F4: 74.790408 | G4: 30.827831 | H4: 42.173155 | I4: 1420.0504 | J4: 1289.7366 | K4: 1384.57 | L4: 528.49344 | M4: 123.50865 | N4: 117.60801 | O4: 1385.9133 | P4: 1199.6668 | Q4: 1203.4092 | R4: 208.56558 | S4: 39.429101 | T4: 48.682908 | U4: 769.2339 | V4: 1077.9388 | W4: 1081.3212 | X4: 67.836698 | Y4: 25.632225 | Z4: 34.347999 | AA4: 703.34855 | AB4: 1276.5279 | AC4: 1339.8504 | AD4: 647.0837 | AE4: 113.49255 | AF4: 106.3444 | AG4: 759.49966 | AH4: 1152.5371 | AI4: 1185.8737 | AJ4: 265.66856 | AK4: 42.108856 | AL4: 42.100927
B5: SD | C5: 14.480014 | D5: 6.2475454 | E5: 9.0354651 | F5: 83.7731 | G5: 29.575882 | H5: 40.235442 | I5: 62.025686 | J5: 15.600902 | K5: 20.046416 | L5: 693.51338 | M5: 161.51302 | N5: 165.95101 | O5: 22.553984 | P5: 5.2663768 | Q5: 10.238077 | R5: 278.7218 | S5: 49.066875 | T5: 48.749837 | U5: 9.4512617 | V5: 5.55755 | W5: 5.6916397 | X5: 59.815919 | Y5: 22.154856 | Z5: 41.49144 | AA5: 69.229129 | AB5: 16.971453 | AC5: 14.85289 | AD5: 1731.192 | AE5: 135.376 | AF5: 144.06354 | AG5: 31.89579 | AH5: 7.0695234 | AI5: 7.1780771 | AJ5: 303.65472 | AK5: 47.050096 | AL5: 36.769147
A6: Con2 | B6: AVG | C6: 1380.946 | D6: 1142.5654 | E6: 1082.2082 | F6: 78.208635 | G6: 28.088253 | H6: 49.11559 | I6: 1423.4598 | J6: 1287.185 | K6: 1376.1175 | L6: 606.95916 | M6: 111.20272 | N6: 181.02298 | O6: 1376.9352 | P6: 1203.0783 | Q6: 1195.0519 | R6: 240.37271 | S6: 36.693235 | T6: 67.298326 | U6: 772.75902 | V6: 1084.5458 | W6: 1077.311 | X6: 70.432359 | Y6: 30.60466 | Z6: 34.657132 | AA6: 704.64345 | AB6: 1264.3582 | AC6: 1344.585 | AD6: 701.71848 | AE6: 138.99353 | AF6: 146.74134 | AG6: 761.727 | AH6: 1150.4021 | AI6: 1184.6808 | AJ6: 296.49955 | AK6: 46.53359 | AL6: 49.155797
B7: SD | C7: 10.650746 | D7: 5.5949193 | E7: 7.9074659 | F7: 81.264733 | G7: 26.488564 | H7: 48.484638 | I7: 64.552517 | J7: 13.22843 | K7: 23.591525 | L7: 747.77851 | M7: 142.72079 | N7: 243.38104 | O7: 25.049014 | P7: 5.607152 | Q7: 10.531808 | R7: 294.40871 | S7: 40.450118 | T7: 67.24708 | U7: 8.8061952 | V7: 6.5062845 | W7: 7.0408393 | X7: 76.3865 | Y7: 25.913885 | Z7: 37.697111 | AA7: 73.330642 | AB7: 17.488682 | AC7: 17.731607 | AD7: 806.06456 | AE7: 158.40473 | AF7: 184.94289 | AG7: 31.983701 | AH7: 6.8299619 | AI7: 7.9498609 | AJ7: 325.36444 | AK7: 55.567222 | AL7: 52.379575
A8: Con3 | B8: AVG | C8: 1380.9184 | D8: 1142.4185 | E8: 1084.0669 | F8: 77.393319 | G8: 29.719375 | H8: 50.316117 | I8: 1425.609 | J8: 1294.7549 | K8: 1375.4437 | L8: 593.90112 | M8: 111.63248 | N8: 149.20432 | O8: 1377.7463 | P8: 1206.0354 | Q8: 1195.7878 | R8: 238.08503 | S8: 36.904458 | T8: 56.625159 | U8: 769.55157 | V8: 1079.8884 | W8: 1082.7936 | X8: 68.837626 | Y8: 34.432091 | Z8: 39.895391 | AA8: 691.27032 | AB8: 1264.2693 | AC8: 1340.6274 | AD8: 781.08498 | AE8: 167.67016 | AF8: 198.89595 | AG8: 754.34129 | AH8: 1148.1772 | AI8: 1187.7317 | AJ8: 328.8165 | AK8: 58.42278 | AL8: 71.43158
B9: SD | C9: 15.30355 | D9: 6.13915 | E9: 10.113713 | F9: 74.951129 | G9: 33.258702 | H9: 49.87441 | I9: 60.546171 | J9: 15.318718 | K9: 21.549531 | L9: 707.8052 | M9: 132.94269 | N9: 219.0976 | O9: 26.221913 | P9: 7.2604385 | Q9: 12.328676 | R9: 282.27986 | S9: 39.144441 | T9: 62.565771 | U9: 10.042119 | V9: 8.480703 | W9: 7.1427656 | X9: 70.538673 | Y9: 29.753382 | Z9: 41.195537 | AA9: 86.582343 | AB9: 22.88248 | AC9: 28.247877 | AD9: 893.08173 | AE9: 203.63702 | AF9: 263.12296 | AG9: 38.280151 | AH9: 9.8844608 | AI9: 10.606491 | AJ9: 355.0112 | AK9: 69.797031 | AL9: 84.558371
A10: Con4 | B10: AVG | C10: 1377.5953 | D10: 1148.1772 | E10: 1084.3429 | F10: 89.36433 | G10: 37.616591 | H10: 55.013588 | I10: 1445.7454 | J10: 1288.4014 | K10: 1372.8385 | L10: 687.182 | M10: 153.1532 | N10: 206.39591 | O10: 1384.1157 | P10: 1207.6372 | Q10: 1196.9855 | R10: 267.89541 | S10: 55.767128 | T10: 86.18343 | U10: 762.28798 | V10: 1079.5643 | W10: 1077.3807 | X10: 95.168772 | Y10: 40.544396 | Z10: 61.688702 | AA10: 675.05985 | AB10: 1260.7367 | AC10: 1331.2128 | AD10: 816.22087 | AE10: 188.70221 | AF10: 206.76315 | AG10: 743.57125 | AH10: 1147.8673 | AI10: 1180.4813 | AJ10: 335.93769 | AK10: 73.141826 | AL10: 68.188641
B11: SD | C11: 11.014931 | D11: 6.7907809 | E11: 8.1183911 | F11: 86.007282 | G11: 48.173783 | H11: 71.082116 | I11: 77.96668 | J11: 18.587358 | K11: 30.020988 | L11: 919.37013 | M11: 196.51293 | N11: 305.47206 | O11: 30.652528 | P11: 6.6277131 | Q11: 12.618691 | R11: 349.92945 | S11: 74.901515 | T11: 110.7183 | U11: 11.869778 | V11: 6.9316588 | W11: 5.1217039 | X11: 116.79932 | Y11: 39.545369 | Z11: 118.79899 | AA11: 98.633006 | AB11: 29.080428 | AC11: 29.755696 | AD11: 1193.089 | AE11: 281.0242 | AF11: 324.49332 | AG11: 43.826846 | AH11: 11.468475 | AI11: 9.2507212 | AJ11: 451.70896 | AK11: 109.70385 | AL11: 99.303815
A12: Con5 | B12: AVG | C12: 1386.0192 | D12: 1153.2498 | E12: 1099.2281 | F12: 117.98776 | G12: 50.953222 | H12: 51.619637 | I12: 1454.7354 | J12: 1309.317 | K12: 1369.5249 | L12: 850.48995 | M12: 291.99124 | N12: 330.29006 | O12: 1389.7884 | P12: 1221.1541 | Q12: 1204.4668 | R12: 314.58789 | S12: 95.766416 | T12: 102.55431 | U12: 747.41072 | V12: 1083.4919 | W12: 1077.2281 | X12: 103.14579 | Y12: 45.571622 | Z12: 56.961111 | AA12: 631.86869 | AB12: 1264.6446 | AC12: 1311.7906 | AD12: 896.45247 | AE12: 231.65672 | AF12: 241.77013 | AG12: 720.49189 | AH12: 1155.647 | AI12: 1170.201 | AJ12: 364.99641 | AK12: 79.780639 | AL12: 77.597662
B13: SD | C13: 17.357032 | D13: 11.340811 | E13: 9.4582801 | F13: 127.16601 | G13: 50.669251 | H13: 42.907627 | I13: 78.808342 | J13: 38.610674 | K13: 42.01637 | L13: 3027.2143 | M13: 429.88339 | N13: 744.82574 | O13: 30.947597 | P13: 10.419716 | Q13: 16.83769 | R13: 489.51106 | S13: 180.34262 | T13: 153.67145 | U13: 14.99274 | V13: 8.5673993 | W13: 11.068194 | X13: 95.426809 | Y13: 39.203611 | Z13: 46.647474 | AA13: 98.883919 | AB13: 34.654443 | AC13: 34.257424 | AD13: 2849.9415 | AE13: 385.603 | AF13: 399.91893 | AG13: 47.135165 | AH13: 13.215027 | AI13: 12.839206 | AJ13: 720.18228 | AK13: 107.58512 | AL13: 84.198915
A14: Con6 | B14: AVG | C14: 1368.4973 | D14: 1161.9696 | E14: 1086.6901 | F14: 151.5917 | G14: 48.37674 | H14: 79.600184 | I14: 1430.1676 | J14: 1309.7927 | K14: 1362.8163 | L14: 987.65785 | M14: 360.32253 | N14: 431.20988 | O14: 1369.3059 | P14: 1225.3099 | Q14: 1195.2589 | R14: 392.59962 | S14: 123.6632 | T14: 148.96833 | U14: 734.43729 | V14: 1076.7714 | W14: 1070.09 | X14: 136.8256 | Y14: 53.961896 | Z14: 81.087993 | AA14: 644.06559 | AB14: 1245.192 | AC14: 1331.2747 | AD14: 938.18676 | AE14: 283.29696 | AF14: 276.99507 | AG14: 716.33567 | AH14: 1145.8405 | AI14: 1172.725 | AJ14: 388.96562 | AK14: 96.958163 | AL14: 94.216276
B15: SD | C15: 20.765851 | D15: 11.6027 | E15: 12.108393 | F15: 150.35178 | G15: 55.251792 | H15: 120.2064 | I15: 88.664094 | J15: 33.490949 | K15: 43.714991 | L15: 1505.0758 | M15: 478.93392 | N15: 693.2785 | O15: 33.92497 | P15: 11.396687 | Q15: 15.60036 | R15: 556.8275 | S15: 166.20737 | T15: 183.21171 | U15: 15.959276 | V15: 12.201454 | W15: 8.6021777 | X15: 158.87829 | Y15: 49.786156 | Z15: 152.63449 | AA15: 95.405935 | AB15: 33.758839 | AC15: 28.388242 | AD15: 1422.927 | AE15: 389.3991 | AF15: 386.28135 | AG15: 43.983377 | AH15: 13.07817 | AI15: 10.830248 | AJ15: 530.18844 | AK15: 130.00564 | AL15: 105.79106
A16: Con7 | B16: AVG | C16: 1454.0611 | D16: 1156.7831 | E16: 1073.7758 | F16: 173.27705 | G16: 63.229845 | H16: 102.9481 | I16: 1536.9646 | J16: 1305.8422 | K16: 1332.4906 | L16: 1142.4619 | M16: 516.61746 | N16: 613.22607 | O16: 1463.7352 | P16: 1221.3394 | Q16: 1177.5615 | R16: 446.80353 | S16: 170.37438 | T16: 196.73039 | U16: 802.67878 | V16: 1052.2693 | W16: 1068.5937 | X16: 153.06847 | Y16: 71.04754 | Z16: 102.47586 | AA16: 688.18599 | AB16: 1230.4379 | AC16: 1301.3396 | AD16: 1007.7193 | AE16: 364.22613 | AF16: 364.44774 | AG16: 777.41246 | AH16: 1128.1897 | AI16: 1157.9017 | AJ16: 426.13026 | AK16: 135.82564 | AL16: 122.1309
B17: SD | C17: 21.409463 | D17: 13.08995 | E17: 14.419089 | F17: 174.24884 | G17: 75.819118 | H17: 158.59578 | I17: 100.11516 | J17: 49.457364 | K17: 61.876009 | L17: 1780.142 | M17: 724.79407 | N17: 1005.5963 | O17: 38.909198 | P17: 16.153588 | Q17: 20.345139 | R17: 639.51102 | S17: 241.81087 | T17: 246.79492 | U17: 18.599338 | V17: 11.03507 | W17: 13.490866 | X17: 170.99086 | Y17: 90.598823 | Z17: 166.29287 | AA17: 106.60174 | AB17: 45.506747 | AC17: 38.479078 | AD17: 1561.1701 | AE17: 510.71848 | AF17: 535.51418 | AG17: 50.481661 | AH17: 16.946846 | AI17: 16.217529 | AJ17: 582.25834 | AK17: 183.69189 | AL17: 152.91182
A18: Con8 | B18: AVG | C18: 1454.7891 | D18: 1154.1729 | E18: 1078.2176 | F18: 163.62359 | G18: 63.220133 | H18: 86.450552 | I18: 1526.4646 | J18: 1299.4808 | K18: 1348.5222 | L18: 1042.2368 | M18: 476.86953 | N18: 526.71895 | O18: 1459.3425 | P18: 1217.0262 | Q18: 1186.0656 | R18: 417.49051 | S18: 157.57915 | T18: 175.45437 | U18: 802.9208 | V18: 1042.4871 | W18: 1064.7499 | X18: 129.20002 | Y18: 70.015214 | Z18: 88.691571 | AA18: 692.83657 | AB18: 1211.7663 | AC18: 1306.236 | AD18: 959.47393 | AE18: 328.53003 | AF18: 351.21104 | AG18: 780.39704 | AH18: 1115.5276 | AI18: 1156.5194 | AJ18: 392.44532 | AK18: 116.53505 | AL18: 114.03151
B19: SD | C19: 22.745782 | D19: 12.973622 | E19: 9.9490222 | F19: 174.01282 | G19: 70.22828 | H19: 139.55153 | I19: 94.526818 | J19: 41.471157 | K19: 54.479162 | L19: 1713.2432 | M19: 680.486 | N19: 917.45888 | O19: 36.745112 | P19: 13.627703 | Q19: 16.011609 | R19: 625.77834 | S19: 218.81885 | T19: 227.84173 | U19: 15.984902 | V19: 11.834539 | W19: 9.898175 | X19: 168.95954 | Y19: 73.343679 | Z19: 168.97727 | AA19: 99.602232 | AB19: 39.76785 | AC19: 34.802494 | AD19: 1568.0205 | AE19: 502.19873 | AF19: 542.35938 | AG19: 45.35225 | AH19: 13.712186 | AI19: 10.579996 | AJ19: 583.96998 | AK19: 169.1515 | AL19: 151.29208
A20: Con9 | B20: AVG | C20: 1459.2308 | D20: 1161.7132 | E20: 1070.1449 | F20: 147.67113 | G20: 52.943577 | H20: 72.896884 | I20: 1492.4894 | J20: 1323.4576 | K20: 1334.0909 | L20: 729.07421 | M20: 279.54232 | N20: 338.09453 | O20: 1448.9528 | P20: 1230.5299 | Q20: 1173.0111 | R20: 310.36333 | S20: 89.994221 | T20: 123.68221 | U20: 804.43276 | V20: 1048.6219 | W20: 1061.6876 | X20: 97.781026 | Y20: 55.556921 | Z20: 54.406378 | AA20: 691.44077 | AB20: 1227.5272 | AC20: 1296.8835 | AD20: 661.40367 | AE20: 277.14614 | AF20: 238.63893 | AG20: 781.88539 | AH20: 1127.3527 | AI20: 1150.4719 | AJ20: 288.53436 | AK20: 97.195762 | AL20: 83.575157
B21: SD | C21: 26.327522 | D21: 15.437718 | E21: 13.326176 | F21: 370.0101 | G21: 101.59847 | H21: 224.98145 | I21: 101.35137 | J21: 41.01236 | K21: 55.586096 | L21: 1058.4764 | M21: 415.80594 | N21: 581.23425 | O21: 40.872384 | P21: 11.898422 | Q21: 18.824623 | R21: 662.28185 | S21: 184.31538 | T21: 318.74289 | U21: 17.13804 | V21: 14.704725 | W21: 10.787733 | X21: 98.682405 | Y21: 54.702895 | Z21: 49.474646 | AA21: 96.874605 | AB21: 41.179514 | AC21: 29.537434 | AD21: 914.27256 | AE21: 347.98827 | AF21: 332.80765 | AG21: 46.30031 | AH21: 15.937611 | AI21: 12.286298 | AJ21: 384.17599 | AK21: 119.32656 | AL21: 88.777505
A22: Con10 | B22: AVG | C22: 1452.8212 | D22: 1155.7615 | E22: 1062.4189 | F22: 129.67747 | G22: 54.707815 | H22: 75.156697 | I22: 1522.5731 | J22: 1308.4967 | K22: 1322.6531 | L22: 803.11153 | M22: 356.65025 | N22: 489.22587 | O22: 1456.5166 | P22: 1221.9484 | Q22: 1166.7114 | R22: 320.64421 | S22: 119.01908 | T22: 150.43848 | U22: 807.10089 | V22: 1045.3717 | W22: 1065.917 | X22: 97.824579 | Y22: 54.718097 | Z22: 57.168809 | AA22: 691.41467 | AB22: 1223.2735 | AC22: 1297.8233 | AD22: 671.7412 | AE22: 276.89766 | AF22: 249.54077 | AG22: 784.29435 | AH22: 1124.1472 | AI22: 1153.1266 | AJ22: 293.82728 | AK22: 97.890686 | AL22: 84.188718
B23: SD | C23: 20.945632 | D23: 13.099663 | E23: 14.927974 | F23: 157.35382 | G23: 64.479613 | H23: 69.955338 | I23: 99.319619 | J23: 43.699194 | K23: 61.337006 | L23: 1153.6421 | M23: 526.59054 | N23: 760.9537 | O23: 38.34657 | P23: 12.168165 | Q23: 20.30834 | R23: 699.89966 | S23: 291.62083 | T23: 383.46948 | U23: 15.143552 | V23: 11.567623 | W23: 11.157473 | X23: 97.988354 | Y23: 51.10768 | Z23: 53.777569 | AA23: 95.048922 | AB23: 42.915111 | AC23: 34.704534 | AD23: 943.18607 | AE23: 358.33404 | AF23: 367.63137 | AG23: 44.272837 | AH23: 15.039937 | AI23: 12.992663 | AJ23: 395.41564 | AK23: 129.5952 | AL23: 121.112
A24: Ctl1 | B24: AVG | C24: 1467.7107 | D24: 1150.0625 | E24: 1076.492 | F24: 119.30358 | G24: 54.77439 | H24: 60.483369 | I24: 1494.6857 | J24: 1304.5614 | K24: 1351.9167 | L24: 705.56513 | M24: 284.76977 | N24: 345.67135 | O24: 1442.7659 | P24: 1216.7111 | Q24: 1181.9486 | R24: 243.23761 | S24: 73.848806 | T24: 89.177488 | U24: 819.55225 | V24: 1068.0203 | W24: 1062.077 | X24: 89.820877 | Y24: 51.30375 | Z24: 66.453111 | AA24: 729.54531 | AB24: 1258.3693 | AC24: 1295.0882 | AD24: 662.36886 | AE24: 229.01802 | AF24: 241.79978 | AG24: 812.05377 | AH24: 1152.8034 | AI24: 1148.0512 | AJ24: 286.40516 | AK24: 77.570945 | AL24: 89.239402
B25: SD | C25: 21.054276 | D25: 14.491485 | E25: 10.712067 | F25: 142.90283 | G25: 58.791745 | H25: 58.178273 | I25: 88.575411 | J25: 35.774342 | K25: 43.045874 | L25: 1047.3341 | M25: 429.30968 | N25: 603.58699 | O25: 46.554636 | P25: 13.766469 | Q25: 14.127906 | R25: 585.03603 | S25: 251.65429 | T25: 221.48809 | U25: 13.431368 | V25: 12.759506 | W25: 16.243877 | X25: 94.594861 | Y25: 49.399881 | Z25: 58.75523 | AA25: 93.348056 | AB25: 33.086913 | AC25: 32.686823 | AD25: 934.60669 | AE25: 276.91916 | AF25: 341.75872 | AG25: 41.872349 | AH25: 10.727731 | AI25: 17.208191 | AJ25: 457.50338 | AK25: 127.99501 | AL25: 135.64148
A26: Ctl2 | B26: AVG | C26: 1455.9064 | D26: 1141.5376 | E26: 1075.3566 | F26: 107.10076 | G26: 48.933891 | H26: 60.723965 | I26: 1498.0577 | J26: 1289.9102 | K26: 1350.4914 | L26: 783.32096 | M26: 281.33731 | N26: 375.82147 | O26: 1439.6458 | P26: 1205.631 | Q26: 1185.1782 | R26: 129.11057 | S26: 64.790127 | T26: 82.427106 | U26: 814.15356 | V26: 1048.5088 | W26: 1063.1055 | X26: 104.61027 | Y26: 54.988397 | Z26: 60.076722 | AA26: 716.6857 | AB26: 1225.1543 | AC26: 1299.0054 | AD26: 710.94819 | AE26: 283.22427 | AF26: 277.00485 | AG26: 812.19392 | AH26: 1131.3569 | AI26: 1152.7496 | AJ26: 261.38543 | AK26: 67.286884 | AL26: 67.027771
B27: SD | C27: 18.318998 | D27: 13.694031 | E27: 12.579981 | F27: 115.03324 | G27: 48.018499 | H27: 56.694498 | I27: 92.269651 | J27: 33.422826 | K27: 41.533074 | L27: 1072.7783 | M27: 382.60235 | N27: 593.56015 | O27: 41.181718 | P27: 13.07333 | Q27: 15.528158 | R27: 187.13577 | S27: 80.313588 | T27: 107.25353 | U27: 14.12021 | V27: 11.202096 | W27: 10.989494 | X27: 107.53578 | Y27: 53.392746 | Z27: 55.688468 | AA27: 104.65466 | AB27: 40.657384 | AC27: 39.038378 | AD27: 977.56179 | AE27: 336.66784 | AF27: 412.21013 | AG27: 40.783681 | AH27: 11.909226 | AI27: 11.545924 | AJ27: 378.82408 | AK27: 82.027475 | AL27: 79.077642
A28: Ctl3 | B28: AVG | C28: 1468.7097 | D28: 1154.487 | E28: 1077.5284 | F28: 110.50495 | G28: 46.228556 | H28: 57.85904 | I28: 1520.6727 | J28: 1318.8946 | K28: 1337.8717 | L28: 746.80248 | M28: 287.24279 | N28: 320.05392 | O28: 1470.823 | P28: 1225.8976 | Q28: 1171.8569 | R28: 171.63465 | S28: 74.359234 | T28: 80.160469 | U28: 817.06115 | V28: 1064.5688 | W28: 1057.0096 | X28: 94.017201 | Y28: 49.916843 | Z28: 57.317527 | AA28: 727.12151 | AB28: 1254.9302 | AC28: 1293.2836 | AD28: 686.45906 | AE28: 242.55326 | AF28: 241.96681 | AG28: 814.37667 | AH28: 1153.5096 | AI28: 1144.6882 | AJ28: 267.55679 | AK28: 62.175417 | AL28: 60.390218
B29: SD | C29: 18.711074 | D29: 9.1938669 | E29: 10.683404 | F29: 110.73782 | G29: 48.573451 | H29: 45.113591 | I29: 78.678373 | J29: 35.73936 | K29: 40.5063 | L29: 1036.1276 | M29: 422.42878 | N29: 512.82798 | O29: 46.843733 | P29: 14.111387 | Q29: 15.562177 | R29: 231.10953 | S29: 102.96323 | T29: 121.67029 | U29: 13.850622 | V29: 10.298985 | W29: 12.032606 | X29: 93.592319 | Y29: 47.380995 | Z29: 56.753762 | AA29: 94.596246 | AB29: 37.66271 | AC29: 33.120676 | AD29: 933.26672 | AE29: 298.79139 | AF29: 337.51005 | AG29: 39.031054 | AH29: 10.139514 | AI29: 13.13104 | AJ29: 363.13383 | AK29: 78.160676 | AL29: 62.053011
A30: Ctl4 | B30: AVG | C30: 1457.1655 | D30: 1158.4157 | E30: 1078.6712 | F30: 108.36166 | G30: 42.598889 | H30: 57.961981 | I30: 1488.7382 | J30: 1312.2967 | K30: 1343.0219 | L30: 783.24357 | M30: 283.30581 | N30: 364.64128 | O30: 1467.3116 | P30: 1220.0043 | Q30: 1171.4177 | R30: 138.41208 | S30: 85.237183 | T30: 117.10284 | U30: 819.94075 | V30: 1056.7067 | W30: 1060.1625 | X30: 102.2675 | Y30: 48.583236 | Z30: 56.397489 | AA30: 724.27555 | AB30: 1239.2697 | AC30: 1297.8878 | AD30: 720.6117 | AE30: 295.82532 | AF30: 271.69136 | AG30: 808.71 | AH30: 1141.9927 | AI30: 1148.2271 | AJ30: 310.77868 | AK30: 92.433243 | AL30: 80.080274
B31: SD | C31: 20.43073 | D31: 11.248326 | E31: 12.961122 | F31: 114.45211 | G31: 43.0533 | H31: 51.173639 | I31: 95.053804 | J31: 36.246672 | K31: 46.606939 | L31: 1088.6305 | M31: 413.13118 | N31: 626.96771 | O31: 55.958623 | P31: 18.075395 | Q31: 16.179203 | R31: 121.63617 | S31: 100.88439 | T31: 153.21898 | U31: 15.071715 | V31: 10.754303 | W31: 13.621408 | X31: 95.312045 | Y31: 48.913201 | Z31: 57.553338 | AA31: 104.19956 | AB31: 44.330248 | AC31: 33.604284 | AD31: 946.26253 | AE31: 365.07505 | AF31: 369.73722 | AG31: 48.142679 | AH31: 15.011917 | AI31: 15.87243 | AJ31: 401.20005 | AK31: 117.39108 | AL31: 82.538917
A32: Ctl5 | B32: AVG | C32: 1447.9082 | D32: 1168.9321 | E32: 1082.1118 | F32: 90.016656 | G32: 39.013406 | H32: 53.177815 | I32: 1499.5013 | J32: 1318.7312 | K32: 1347.9564 | L32: 744.11601 | M32: 289.83506 | N32: 359.80607 | O32: 1461.0979 | P32: 1222.0206 | Q32: 1177.3447 | R32: 128.53668 | S32: 81.743955 | T32: 104.35502 | U32: 817.8728 | V32: 1060.8901 | W32: 1068.7841 | X32: 102.67861 | Y32: 60.408988 | Z32: 55.583177 | AA32: 745.51565 | AB32: 1249.0017 | AC32: 1313.6754 | AD32: 726.54791 | AE32: 302.54516 | AF32: 237.56332 | AG32: 815.98744 | AH32: 1147.2005 | AI32: 1157.7689 | AJ32: 294.74495 | AK32: 85.636216 | AL32: 68.283854
B33: SD | C33: 15.368953 | D33: 10.430347 | E33: 11.34837 | F33: 99.336305 | G33: 38.681924 | H33: 46.19919 | I33: 86.008597 | J33: 34.733031 | K33: 45.78964 | L33: 1060.2906 | M33: 432.23164 | N33: 633.54953 | O33: 59.640601 | P33: 12.044024 | Q33: 18.447014 | R33: 121.24284 | S33: 107.25046 | T33: 152.38224 | U33: 13.847218 | V33: 11.246963 | W33: 11.00072 | X33: 99.839851 | Y33: 55.190218 | Z33: 51.700034 | AA33: 96.89073 | AB33: 38.456791 | AC33: 23.550726 | AD33: 958.52442 | AE33: 370.71315 | AF33: 310.71516 | AG33: 42.352093 | AH33: 12.849594 | AI33: 11.078682 | AJ33: 375.81282 | AK33: 100.78271 | AL33: 59.160384
A34: Ctl6 | B34: AVG | C34: 1451.1345 | D34: 1168.3132 | E34: 1086.4766 | F34: 99.162989 | G34: 38.946283 | H34: 54.160083 | I34: 1495.6578 | J34: 1318.3269 | K34: 1344.7726 | L34: 752.77903 | M34: 296.24632 | N34: 416.00159 | O34: 1506.8108 | P34: 1220.2066 | Q34: 1170.0522 | R34: 184.60801 | S34: 129.69565 | T34: 215.97456 | U34: 812.58004 | V34: 1041.2151 | W34: 1072.5403 | X34: 102.2158 | Y34: 55.295125 | Z34: 58.782346 | AA34: 727.84951 | AB34: 1217.0807 | AC34: 1315.4458 | AD34: 741.86818 | AE34: 324.43727 | AF34: 276.16312 | AG34: 810.23426 | AH34: 1124.8527 | AI34: 1161.246 | AJ34: 283.47401 | AK34: 83.567953 | AL34: 66.49476
B35: SD | C35: 16.942857 | D35: 11.453959 | E35: 11.006955 | F35: 100.00345 | G35: 39.121231 | H35: 46.660045 | I35: 101.84942 | J35: 38.199922 | K35: 55.527746 | L35: 1104.2245 | M35: 437.82017 | N35: 702.36537 | O35: 40.729116 | P35: 20.07305 | Q35: 24.318083 | R35: 129.55119 | S35: 121.41715 | T35: 246.64176 | U35: 14.374278 | V35: 13.405693 | W35: 11.567532 | X35: 98.213444 | Y35: 51.337491 | Z35: 55.076602 | AA35: 104.24687 | AB35: 42.867915 | AC35: 30.275219 | AD35: 978.64092 | AE35: 401.68705 | AF35: 380.63605 | AG35: 44.661376 | AH35: 13.955964 | AI35: 12.783278 | AJ35: 394.18228 | AK35: 110.93037 | AL35: 69.346089
A36: Ctl7 | B36: AVG | C36: 1444.8796 | D36: 1179.0446 | E36: 1084.8678 | F36: 105.15922 | G36: 41.429347 | H36: 54.794764 | I36: 1480.1998 | J36: 1332.3113 | K36: 1347.8817 | L36: 787.7413 | M36: 298.73129 | N36: 407.01758 | O36: 1485.4056 | P36: 1233.8681 | Q36: 1173.1667 | R36: 205.646 | S36: 131.74158 | T36: 191.08538 | U36: 810.48186 | V36: 1052.5205 | W36: 1082.4456 | X36: 99.079201 | Y36: 53.548469 | Z36: 53.715112 | AA36: 733.70714 | AB36: 1227.7645 | AC36: 1329.7064 | AD36: 692.31802 | AE36: 315.39566 | AF36: 249.96051 | AG36: 805.00481 | AH36: 1133.6631 | AI36: 1171.9753 | AJ36: 302.18245 | AK36: 104.25813 | AL36: 80.766953
B37: SD | C37: 15.976284 | D37: 9.3993031 | E37: 11.994027 | F37: 111.38667 | G37: 40.280442 | H37: 49.914807 | I37: 92.832192 | J37: 36.684015 | K37: 53.872514 | L37: 1129.9828 | M37: 455.19658 | N37: 716.69267 | O37: 47.853522 | P37: 16.101765 | Q37: 20.210551 | R37: 172.7904 | S37: 129.98076 | T37: 202.25206 | U37: 14.27193 | V37: 9.0595514 | W37: 10.631771 | X37: 96.052903 | Y37: 52.446489 | Z37: 53.511616 | AA37: 104.41825 | AB37: 44.416204 | AC37: 31.726787 | AD37: 915.58443 | AE37: 391.8958 | AF37: 360.47401 | AG37: 45.792312 | AH37: 14.87319 | AI37: 10.921269 | AJ37: 383.13989 | AK37: 131.73938 | AL37: 85.846837
A38: Ctl8 | B38: AVG | C38: 1447.6396 | D38: 1180.2669 | E38: 1083.9979 | F38: 112.22632 | G38: 40.695968 | H38: 54.579885 | I38: 1483.0444 | J38: 1330.8124 | K38: 1344.0847 | L38: 841.58284 | M38: 351.73055 | N38: 458.06347 | O38: 1478.2888 | P38: 1235.2182 | Q38: 1171.7431 | R38: 270.29351 | S38: 180.16526 | T38: 205.51635 | U38: 805.57905 | V38: 1034.3726 | W38: 1074.1084 | X38: 107.31102 | Y38: 65.526232 | Z38: 61.66523 | AA38: 719.27242 | AB38: 1204.5336 | AC38: 1321.2034 | AD38: 722.90535 | AE38: 382.34446 | AF38: 280.50534 | AG38: 793.26237 | AH38: 1113.1039 | AI38: 1164.4011 | AJ38: 321.13189 | AK38: 134.13131 | AL38: 95.971708
B39: SD | C39: 19.077059 | D39: 12.180945 | E39: 8.5254245 | F39: 123.96719 | G39: 40.523206 | H39: 46.891821 | I39: 98.777207 | J39: 38.881081 | K39: 53.340644 | L39: 1209.1952 | M39: 532.91676 | N39: 787.57266 | O39: 52.012403 | P39: 17.174067 | Q39: 18.805483 | R39: 270.17011 | S39: 171.16743 | T39: 192.19419 | U39: 15.6247 | V39: 11.029082 | W39: 12.720056 | X39: 106.4901 | Y39: 63.407539 | Z39: 55.47372 | AA39: 103.86954 | AB39: 52.055123 | AC39: 31.54401 | AD39: 979.92525 | AE39: 504.07683 | AF39: 384.33596 | AG39: 47.967461 | AH39: 16.98261 | AI39: 13.681812 | AJ39: 420.25599 | AK39: 172.30814 | AL39: 93.805294
A40: Ctl9 | B40: AVG | C40: 1454.5092 | D40: 1181.8163 | E40: 1085.2964 | F40: 112.48905 | G40: 43.633617 | H40: 64.965383 | I40: 1505.4806 | J40: 1330.5444 | K40: 1348.3102 | L40: 798.4406 | M40: 327.23791 | N40: 423.51372 | O40: 1489.9259 | P40: 1236.372 | Q40: 1176.4853 | R40: 215.99052 | S40: 124.73211 | T40: 191.1267 | U40: 811.45341 | V40: 1045.2513 | W40: 1074.8602 | X40: 105.45909 | Y40: 60.742901 | Z40: 66.254018 | AA40: 742.92116 | AB40: 1232.2961 | AC40: 1319.9393 | AD40: 672.30369 | AE40: 304.93648 | AF40: 235.4287 | AG40: 807.78427 | AH40: 1129.9847 | AI40: 1162.3362 | AJ40: 294.249 | AK40: 99.899701 | AL40: 89.85152
...

Sheet P3
B1: Marker | C1: LeftMallet1 | I1: LeftMallet2 | O1: LeftMallet3 | U1: RightMallet1 | AA1: RightMallet2 | AG1: RightMallet3
B2: Axis | C2: X | D2: Y | E2: Z | F2: X' | G2: Y' | H2: Z' | I2: X | J2: Y | K2: Z | L2: X' | M2: Y' | N2: Z' | O2: X | P2: Y | Q2: Z | R2: X' | S2: Y' | T2: Z' | U2: X | V2: Y | W2: Z | X2: X' | Y2: Y' | Z2: Z' | AA2: X | AB2: Y | AC2: Z | AD2: X' | AE2: Y' | AF2: Z' | AG2: X | AH2: Y | AI2: Z | AJ2: X' | AK2: Y' | AL2: Z'
A3: Trial | B3: Stats
A4: Con01 | B4: AVG | C4: 1314.8357 | D4: 839.06094 | E4: 1169.6269 | F4: 99.760442 | G4: 45.233501 | H4: 72.210327 | I4: 1351.0764 | J4: 1111.2491 | K4: 1334.6568 | L4: 300.74058 | M4: 63.611624 | N4: 109.85316 | O4: 1310.8309 | P4: 933.89287 | Q4: 1232.3029 | R4: 182.93839 | S4: 37.120809 | T4: 72.560854 | U4: 675.36296 | V4: 810.52032 | W4: 1186.4284 | X4: 67.897013 | Y4: 41.512276 | Z4: 58.355443 | AA4: 606.66348 | AB4: 1107.1832 | AC4: 1314.4698 | AD4: 375.36161 | AE4: 96.174212 | AF4: 124.489 | AG4: 674.9799 | AH4: 923.90826 | AI4: 1245.3933 | AJ4: 176.90718 | AK4: 42.178795 | AL4: 71.400655
B5: SD | C5: 14.422703 | D5: 9.0702192 | E5: 12.162669 | F5: 100.21956 | G5: 38.299675 | H5: 45.986555 | I5: 55.137449 | J5: 14.404429 | K5: 17.728396 | L5: 342.68858 | M5: 61.438782 | N5: 86.3193 | O5: 28.583766 | P5: 9.3919161 | Q5: 12.586016 | R5: 202.89206 | S5: 33.369855 | T5: 52.338388 | U5: 12.692461 | V5: 8.0452848 | W5: 13.964564 | X5: 67.324642 | Y5: 30.534846 | Z5: 45.468128 | AA5: 63.2944 | AB5: 14.743443 | AC5: 24.709403 | AD5: 429.3302 | AE5: 87.724691 | AF5: 97.323249 | AG5: 31.329459 | AH5: 7.3975152 | AI5: 16.573646 | AJ5: 196.91591 | AK5: 33.015704 | AL5: 57.372295
A6: Con02 | B6: AVG | C6: 1334.3645 | D6: 844.01431 | E6: 1179.8067 | F6: 102.01023 | G6: 41.535019 | H6: 65.213601 | I6: 1351.9614 | J6: 1120.1401 | K6: 1333.7445 | L6: 271.56107 | M6: 50.535137 | N6: 100.01778 | O6: 1319.4976 | P6: 934.78966 | Q6: 1243.487 | R6: 178.15636 | S6: 29.239466 | T6: 64.312521 | U6: 697.83444 | V6: 786.02206 | W6: 1185.656 | X6: 74.664317 | Y6: 52.805572 | Z6: 73.38058 | AA6: 597.45258 | AB6: 1071.0311 | AC6: 1285.6044 | AD6: 432.13088 | AE6: 138.16862 | AF6: 176.19128 | AG6: 689.67812 | AH6: 893.30959 | AI6: 1237.2823 | AJ6: 206.59226 | AK6: 56.654162 | AL6: 99.893857
B7: SD | C7: 14.530073 | D7: 9.8482946 | E7: 11.93906 | F7: 103.72285 | G7: 34.583032 | H7: 38.436202 | I7: 53.862636 | J7: 11.750118 | K7: 20.857169 | L7: 349.32291 | M7: 52.321877 | N7: 83.240995 | O7: 27.147392 | P7: 8.5756511 | Q7: 13.60733 | R7: 204.7869 | S7: 25.81423 | T7: 46.167462 | U7: 15.782654 | V7: 9.9151832 | W7: 18.504818 | X7: 74.571854 | Y7: 35.867882 | Z7: 58.377609 | AA7: 72.971574 | AB7: 19.264841 | AC7: 40.179803 | AD7: 476.26189 | AE7: 124.51285 | AF7: 160.04977 | AG7: 36.901294 | AH7: 8.4853459 | AI7: 23.865094 | AJ7: 213.67422 | AK7: 43.76647 | AL7: 88.234546
A8: Con03 | B8: AVG | C8: 1336.9578 | D8: 842.89477 | E8: 1164.787 | F8: 117.01936 | G8: 38.202003 | H8: 64.473938 | I8: 1386.7311 | J8: 1116.7127 | K8: 1311.3074 | L8: 397.25948 | M8: 68.981955 | N8: 133.55315 | O8: 1337.256 | P8: 935.56032 | Q8: 1223.9399 | R8: 219.40966 | S8: 35.733898 | T8: 73.174822 | U8: 703.96399 | V8: 762.76091 | W8: 1182.8968 | X8: 74.158155 | Y8: 60.630548 | Z8: 73.068588 | AA8: 594.03826 | AB8: 1048.4144 | AC8: 1262.8026 | AD8: 423.61529 | AE8: 147.26344 | AF8: 178.69476 | AG8: 692.29273 | AH8: 870.49178 | AI8: 1228.8424 | AJ8: 205.44531 | AK8: 63.513175 | AL8: 100.82134
B9: SD | C9: 16.204962 | D9: 9.9685565 | E9: 9.9613366 | F9: 120.00628 | G9: 28.215028 | H9: 39.605396 | I9: 66.09985 | J9: 13.84444 | K9: 23.380974 | L9: 504.02492 | M9: 66.048469 | N9: 96.190394 | O9: 32.464072 | P9: 9.7946621 | Q9: 12.743806 | R9: 253.92705 | S9: 29.125438 | T9: 49.656395 | U9: 14.725949 | V9: 10.790799 | W9: 17.068237 | X9: 71.772306 | Y9: 40.479962 | Z9: 51.533107 | AA9: 70.697081 | AB9: 22.573533 | AC9: 38.852845 | AD9: 465.81547 | AE9: 137.32604 | AF9: 148.46372 | AG9: 35.423893 | AH9: 10.148528 | AI9: 22.928494 | AJ9: 208.97797 | AK9: 50.772853 | AL9: 81.052892
A10: Con04 | B10: AVG | C10: 1339.124 | D10: 849.43699 | E10: 1172.4205 | F10: 112.48149 | G10: 43.669123 | H10: 69.626573 | I10: 1372.0861 | J10: 1122.8208 | K10: 1308.6386 | L10: 367.44751 | M10: 56.355362 | N10: 130.04316 | O10: 1327.7155 | P10: 943.37743 | Q10: 1213.4844 | R10: 205.72304 | S10: 33.086137 | T10: 76.021435 | U10: 706.96669 | V10: 754.94787 | W10: 1173.3115 | X10: 67.461752 | Y10: 60.465969 | Z10: 84.27525 | AA10: 587.79648 | AB10: 1037.5176 | AC10: 1247.4348 | AD10: 418.81638 | AE10: 154.88222 | AF10: 224.12559 | AG10: 691.403 | AH10: 862.05041 | AI10: 1218.2457 | AJ10: 202.1125 | AK10: 67.035893 | AL10: 122.69297
B11: SD | C11: 16.443834 | D11: 7.7822661 | E11: 10.822277 | F11: 115.44036 | G11: 34.15089 | H11: 44.459934 | I11: 64.196132 | J11: 10.65762 | K11: 22.994092 | L11: 442.50607 | M11: 58.246302 | N11: 104.53213 | O11: 31.93933 | P11: 6.1557503 | Q11: 13.203591 | R11: 234.1108 | S11: 28.369349 | T11: 57.74107 | U11: 13.786529 | V11: 11.473102 | W11: 20.724822 | X11: 68.129608 | Y11: 43.079297 | Z11: 66.04479 | AA11: 67.57725 | AB11: 22.712579 | AC11: 50.468899 | AD11: 467.97578 | AE11: 139.56179 | AF11: 187.02377 | AG11: 33.915145 | AH11: 11.024055 | AI11: 29.259025 | AJ11: 208.80337 | AK11: 51.665362 | AL11: 105.54818
A12: Con05 | B12: AVG | C12: 1341.6494 | D12: 861.96022 | E12: 1176.5724 | F12: 106.28478 | G12: 35.265049 | H12: 66.813881 | I12: 1360.5319 | J12: 1134.2023 | K12: 1318.526 | L12: 296.8833 | M12: 49.185632 | N12: 135.84847 | O12: 1324.8228 | P12: 953.51268 | Q12: 1220.8427 | R12: 190.80134 | S12: 32.077951 | T12: 80.030862 | U12: 707.24668 | V12: 746.27108 | W12: 1171.0732 | X12: 73.282596 | Y12: 67.687601 | Z12: 86.697505 | AA12: 577.41752 | AB12: 1022.9424 | AC12: 1236.3067 | AD12: 463.00072 | AE12: 189.68407 | AF12: 241.16589 | AG12: 686.38095 | AH12: 851.58292 | AI12: 1213.9318 | AJ12: 225.82162 | AK12: 82.064013 | AL12: 132.72733
B13: SD | C13: 16.67117 | D13: 9.0174922 | E13: 11.431482 | F13: 110.21234 | G13: 23.944978 | H13: 44.387415 | I13: 57.480539 | J13: 11.416902 | K13: 26.114227 | L13: 369.5165 | M13: 49.071608 | N13: 114.35025 | O13: 29.807604 | P13: 7.4134055 | Q13: 14.339869 | R13: 221.85425 | S13: 26.91959 | T13: 60.185603 | U13: 15.339364 | V13: 12.739833 | W13: 23.328334 | X13: 71.489828 | Y13: 47.974287 | Z13: 68.556496 | AA13: 77.605843 | AB13: 29.684633 | AC13: 55.065087 | AD13: 496.87987 | AE13: 170.99261 | AF13: 195.76746 | AG13: 39.065571 | AH13: 12.701424 | AI13: 31.909947 | AJ13: 220.95729 | AK13: 63.206589 | AL13: 108.94594
A14: Con06 | B14: AVG | C14: 1333.2962 | D14: 878.46393 | E14: 1171.4776 | F14: 109.08683 | G14: 37.456425 | H14: 71.995229 | I14: 1341.6047 | J14: 1158.887 | K14: 1294.158 | L14: 293.94411 | M14: 42.132808 | N14: 147.55497 | O14: 1310.8583 | P14: 970.93927 | Q14: 1211.3687 | R14: 200.2734 | S14: 39.565424 | T14: 86.226487 | U14: 700.95502 | V14: 736.98009 | W14: 1162.1175 | X14: 71.73417 | Y14: 66.084661 | Z14: 83.890837 | AA14: 549.31453 | AB14: 1003.1618 | AC14: 1217.9193 | AD14: 476.40728 | AE14: 216.91089 | AF14: 263.39731 | AG14: 670.3796 | AH14: 839.71228 | AI14: 1202.4774 | AJ14: 232.7505 | AK14: 89.13845 | AL14: 140.96934
B15: SD | C15: 16.222568 | D15: 11.985986 | E15: 13.978881 | F15: 115.37878 | G15: 26.402598 | H15: 49.74581 | I15: 60.447926 | J15: 18.306124 | K15: 31.913991 | L15: 367.47622 | M15: 42.165919 | N15: 125.19255 | O15: 31.168087 | P15: 11.551569 | Q15: 17.949053 | R15: 229.57131 | S15: 37.787384 | T15: 65.767111 | U15: 15.355849 | V15: 13.330066 | W15: 22.616909 | X15: 75.932465 | Y15: 52.479481 | Z15: 70.954126 | AA15: 78.362873 | AB15: 34.977008 | AC15: 55.896421 | AD15: 512.2902 | AE15: 197.00305 | AF15: 203.07318 | AG15: 40.10272 | AH15: 14.960625 | AI15: 31.668032 | AJ15: 229.22351 | AK15: 71.295204 | AL15: 110.07031
A16: Con07 | B16: AVG | C16: 1339.5523 | D16: 874.80912 | E16: 1156.2421 | F16: 118.51218 | G16: 35.53321 | H16: 78.202789 | I16: 1366.3241 | J16: 1156.9912 | K16: 1267.694 | L16: 326.24415 | M16: 53.218574 | N16: 170.07608 | O16: 1323.0142 | P16: 968.00912 | Q16: 1193.3545 | R16: 214.5015 | S16: 38.377254 | T16: 92.822982 | U16: 707.08048 | V16: 738.99319 | W16: 1156.1545 | X16: 64.519238 | Y16: 56.60933 | Z16: 83.193399 | AA16: 564.65362 | AB16: 1011.5631 | AC16: 1202.3869 | AD16: 471.65666 | AE16: 214.96322 | AF16: 285.45145 | AG16: 680.34357 | AH16: 844.12877 | AI16: 1192.7769 | AJ16: 225.83105 | AK16: 81.875701 | AL16: 153.50944
B17: SD | C17: 18.718656 | D17: 14.624364 | E17: 13.450225 | F17: 126.7139 | G17: 25.266205 | H17: 53.223128 | I17: 66.012575 | J17: 18.586368 | K17: 29.011949 | L17: 411.95311 | M17: 56.644582 | N17: 138.54072 | O17: 34.922645 | P17: 13.347359 | Q17: 16.338975 | R17: 250.95932 | S17: 37.601076 | T17: 70.836799 | U17: 15.971766 | V17: 13.434891 | W17: 21.693158 | X17: 72.952107 | Y17: 44.700669 | Z17: 68.786339 | AA17: 77.335066 | AB17: 34.614055 | AC17: 56.366579 | AD17: 498.64663 | AE17: 202.74828 | AF17: 219.62622 | AG17: 38.950135 | AH17: 14.030278 | AI17: 31.867972 | AJ17: 221.22422 | AK17: 69.263339 | AL17: 116.92921
A18: Con08 | B18: AVG | C18: 1335.1958 | D18: 874.85706 | E18: 1157.9956 | F18: 112.52293 | G18: 37.415399 | H18: 72.60225 | I18: 1344.3852 | J18: 1146.2946 | K18: 1283.46 | L18: 298.09381 | M18: 44.388774 | N18: 158.68824 | O18: 1296.969 | P18: 965.74676 | Q18: 1193.2775 | R18: 46.01596 | S18: 9.8337814 | T18: 24.549953 | U18: 707.66134 | V18: 737.73373 | W18: 1148.7861 | X18: 64.390116 | Y18: 64.882067 | Z18: 76.397507 | AA18: 568.12137 | AB18: 1009.8542 | AC18: 1204.1829 | AD18: 468.03393 | AE18: 220.27281 | AF18: 271.64859 | AG18: 683.18896 | AH18: 842.66813 | AI18: 1187.719 | AJ18: 222.0015 | AK18: 88.156912 | AL18: 142.70518
B19: SD | C19: 16.673136 | D19: 13.795974 | E19: 14.296862 | F19: 122.0463 | G19: 27.632349 | H19: 53.073796 | I19: 62.609477 | J19: 17.248943 | K19: 30.007222 | L19: 350.31284 | M19: 52.166096 | N19: 147.44387 | O19: 29.066811 | P19: 12.121276 | Q19: 14.491814 | R19: 103.36541 | S19: 18.417458 | T19: 40.249135 | U19: 15.016804 | V19: 13.035277 | W19: 20.602749 | X19: 68.719485 | Y19: 50.007312 | Z19: 67.074805 | AA19: 75.832288 | AB19: 35.394472 | AC19: 57.768099 | AD19: 497.35685 | AE19: 199.60361 | AF19: 215.75001 | AG19: 38.217329 | AH19: 14.199854 | AI19: 31.345074 | AJ19: 220.76642 | AK19: 70.625786 | AL19: 114.30304
A20: Con09 | B20: AVG | C20: 1343.3892 | D20: 859.69547 | E20: 1163.882 | F20: 105.61624 | G20: 38.857266 | H20: 73.80713 | I20: 1362.165 | J20: 1133.0395 | K20: 1290.8585 | L20: 308.48031 | M20: 54.237751 | N20: 152.79485 | O20: 1311.7494 | P20: 956.13747 | Q20: 1196.9149 | R20: 86.807401 | S20: 11.883151 | T20: 47.538988 | U20: 711.378 | V20: 736.47789 | W20: 1155.026 | X20: 68.179576 | Y20: 54.066283 | Z20: 71.42253 | AA20: 578.02539 | AB20: 1007.6044 | AC20: 1222.9303 | AD20: 487.72094 | AE20: 215.14623 | AF20: 255.66565 | AG20: 688.89003 | AH20: 838.99202 | AI20: 1198.8868 | AJ20: 233.7806 | AK20: 82.398658 | AL20: 133.81828
B21: SD | C21: 16.075327 | D21: 13.278839 | E21: 12.515012 | F21: 118.30303 | G21: 34.448073 | H21: 51.082968 | I21: 68.500986 | J21: 18.597065 | K21: 27.307331 | L21: 384.52259 | M21: 65.444425 | N21: 135.93313 | O21: 30.723472 | P21: 10.915334 | Q21: 13.13047 | R21: 149.00415 | S21: 17.440581 | T21: 58.969648 | U21: 14.424147 | V21: 12.732289 | W21: 18.769972 | X21: 77.039981 | Y21: 44.561999 | Z21: 61.172508 | AA21: 82.101618 | AB21: 35.837287 | AC21: 51.355888 | AD21: 511.54995 | AE21: 201.06214 | AF21: 203.70979 | AG21: 40.321199 | AH21: 14.308313 | AI21: 27.703184 | AJ21: 228.13168 | AK21: 71.197109 | AL21: 107.58062
A22: Con10 | B22: AVG | C22: 1338.5098 | D22: 864.64822 | E22: 1147.7851 | F22: 114.89296 | G22: 38.485879 | H22: 81.707712 | I22: 1364.0271 | J22: 1144.3137 | K22: 1277.2014 | L22: 366.49814 | M22: 67.273412 | N22: 178.46813 | O22: 1321.7388 | P22: 961.41134 | Q22: 1189.8103 | R22: 223.98709 | S22: 36.279286 | T22: 93.771126 | U22: 708.51687 | V22: 731.22113 | W22: 1149.8965 | X22: 70.038057 | Y22: 58.592244 | Z22: 72.65381 | AA22: 571.69832 | AB22: 1001.0272 | AC22: 1210.7179 | AD22: 476.93773 | AE22: 228.28003 | AF22: 252.92252 | AG22: 684.98295 | AH22: 834.35918 | AI22: 1189.7557 | AJ22: 227.51202 | AK22: 88.740425 | AL22: 133.42399
